<?xml version="1.0" encoding="utf-8"?>
<!-- This URDF was automatically created by SolidWorks to URDF Exporter! Originally created by Stephen Brawner (brawner@gmail.com) 
     Commit Version: 1.6.0-4-g7f85cfe  Build Version: 1.6.7995.38578
     For more information, please see http://wiki.ros.org/sw_urdf_exporter -->
<robot
  name="Mario_Assembly">
  <link
    name="Link_1">
    <inertial>
      <origin
        xyz="0.0041195959433721 0.00474968738105286 0.0289356503363691"
        rpy="0 0 0" />
      <mass
        value="0.214712543801582" />
      <inertia
        ixx="0.00010967808746877"
        ixy="-1.0338372982007E-07"
        ixz="-1.11754917199067E-08"
        iyy="8.35184775203106E-05"
        iyz="3.3909748429294E-08"
        izz="0.000184527790301755" />
    </inertial>
    <visual>
      <origin
        xyz="0 0 0"
        rpy="0 0 0" />
      <geometry>
        <mesh
          filename="package://Mario_Assembly/meshes/Link_1.STL" />
      </geometry>
      <material
        name="">
        <color
          rgba="0.627450980392157 0.627450980392157 0.627450980392157 1" />
      </material>
    </visual>
    <collision>
      <origin
        xyz="0 0 0"
        rpy="0 0 0" />
      <geometry>
        <mesh
          filename="package://Mario_Assembly/meshes/Link_1.STL" />
      </geometry>
    </collision>
  </link>
  <link
    name="Link_2">
    <inertial>
      <origin
        xyz="0.00844494644797055 -0.014373202054543 0.0219378314160253"
        rpy="0 0 0" />
      <mass
        value="0.0265256898848201" />
      <inertia
        ixx="5.07905383664275E-06"
        ixy="-1.89949777750374E-06"
        ixz="5.62670436619023E-09"
        iyy="7.27239464343923E-06"
        iyz="-1.13772261296904E-08"
        izz="8.11525741647489E-06" />
    </inertial>
    <visual>
      <origin
        xyz="0 0 0"
        rpy="0 0 0" />
      <geometry>
        <mesh
          filename="package://Mario_Assembly/meshes/Link_2.STL" />
      </geometry>
      <material
        name="">
        <color
          rgba="0.792156862745098 0.819607843137255 0.933333333333333 1" />
      </material>
    </visual>
    <collision>
      <origin
        xyz="0 0 0"
        rpy="0 0 0" />
      <geometry>
        <mesh
          filename="package://Mario_Assembly/meshes/Link_2.STL" />
      </geometry>
    </collision>
  </link>
  <joint
    name="Joint_1"
    type="continuous">
    <origin
      xyz="0 0 0.0791"
      rpy="0 0 -0.10872" />
    <parent
      link="Link_1" />
    <child
      link="Link_2" />
    <axis
      xyz="0 0 1" />
  </joint>
  <link
    name="Link_3">
    <inertial>
      <origin
        xyz="0.0415244195997565 -0.0129071157484673 0.0173525674706036"
        rpy="0 0 0" />
      <mass
        value="0.0151482076710041" />
      <inertia
        ixx="9.89600577660498E-07"
        ixy="-1.16832960218687E-08"
        ixz="-1.13095249415414E-06"
        iyy="4.08760796218019E-06"
        iyz="-4.89230666582289E-09"
        izz="3.24049453369696E-06" />
    </inertial>
    <visual>
      <origin
        xyz="0 0 0"
        rpy="0 0 0" />
      <geometry>
        <mesh
          filename="package://Mario_Assembly/meshes/Link_3.STL" />
      </geometry>
      <material
        name="">
        <color
          rgba="1 1 1 1" />
      </material>
    </visual>
    <collision>
      <origin
        xyz="0 0 0"
        rpy="0 0 0" />
      <geometry>
        <mesh
          filename="package://Mario_Assembly/meshes/Link_3.STL" />
      </geometry>
    </collision>
  </link>
  <joint
    name="Joint_2"
    type="continuous">
    <origin
      xyz="0.0001882 0.00010866 0.041252"
      rpy="0 0 0.5236" />
    <parent
      link="Link_2" />
    <child
      link="Link_3" />
    <axis
      xyz="0 1 0" />
  </joint>
  <link
    name="Link_4">
    <inertial>
      <origin
        xyz="6.81242883400768E-05 0.00544054198441336 -0.050702180874678"
        rpy="0 0 0" />
      <mass
        value="0.0134427034473215" />
      <inertia
        ixx="6.18410233101787E-06"
        ixy="-9.60758244313861E-10"
        ixz="5.33916891854104E-08"
        iyy="5.76244797172349E-06"
        iyz="1.04670762378509E-07"
        izz="1.20929671367831E-06" />
    </inertial>
    <visual>
      <origin
        xyz="0 0 0"
        rpy="0 0 0" />
      <geometry>
        <mesh
          filename="package://Mario_Assembly/meshes/Link_4.STL" />
      </geometry>
      <material
        name="">
        <color
          rgba="0.792156862745098 0.819607843137255 0.933333333333333 1" />
      </material>
    </visual>
    <collision>
      <origin
        xyz="0 0 0"
        rpy="0 0 0" />
      <geometry>
        <mesh
          filename="package://Mario_Assembly/meshes/Link_4.STL" />
      </geometry>
    </collision>
  </link>
  <joint
    name="Joint_3"
    type="continuous">
    <origin
      xyz="0.05866 0 0.024588"
      rpy="0 -0.39691 0" />
    <parent
      link="Link_3" />
    <child
      link="Link_4" />
    <axis
      xyz="0 1 0" />
  </joint>
  <link
    name="Gripper">
    <inertial>
      <origin
        xyz="-0.00103575530339417 -0.0150506847386816 -0.00770061041542727"
        rpy="0 0 0" />
      <mass
        value="0.0362377387684965" />
      <inertia
        ixx="7.24170443133569E-06"
        ixy="1.2661855343743E-08"
        ixz="3.65846228261207E-12"
        iyy="5.71598842039774E-06"
        iyz="1.88317583468337E-07"
        izz="1.67751526700136E-06" />
    </inertial>
    <visual>
      <origin
        xyz="0 0 0"
        rpy="0 0 0" />
      <geometry>
        <mesh
          filename="package://Mario_Assembly/meshes/Gripper.STL" />
      </geometry>
      <material
        name="">
        <color
          rgba="0.776470588235294 0.756862745098039 0.737254901960784 1" />
      </material>
    </visual>
    <collision>
      <origin
        xyz="0 0 0"
        rpy="0 0 0" />
      <geometry>
        <mesh
          filename="package://Mario_Assembly/meshes/Gripper.STL" />
      </geometry>
    </collision>
  </link>
  <joint
    name="Joint_4"
    type="continuous">
    <origin
      xyz="0.00082495 0.018376 -0.089872"
      rpy="0 -0.0091789 0" />
    <parent
      link="Link_4" />
    <child
      link="Gripper" />
    <axis
      xyz="1 0 0" />
  </joint>
</robot>